Workbook

Sheet Dashboard
A1: Laura Gao Portfolio — Strategy Dashboard (Monte Carlo / Markov + Glide Path Model)
A2: 500-trial simulation — growth bucket now de-risks into bonds in Years 5–6 (2031–32). Recalculates on refresh (F9).
A4: 1. Growth Bucket — Simulated Portfolio Value at Start of 2033 (Year 7)
A6: Percentile | B6: Portfolio Value ($)
A7: 5th (downside) | B7: =PERCENTILE(Growth_MC!AE2:AE501,0.05) -> 261669.01
A8: 25th | B8: =PERCENTILE(Growth_MC!AE2:AE501,0.25) -> 477321.86
A9: 50th (Median) | B9: =PERCENTILE(Growth_MC!AE2:AE501,0.5) -> 705852.61
A10: 75th | B10: =PERCENTILE(Growth_MC!AE2:AE501,0.75) -> 898081.15
A11: 95th (upside) | B11: =PERCENTILE(Growth_MC!AE2:AE501,0.95) -> 1193857.8
A12: Mean | B12: =AVERAGE(Growth_MC!AE2:AE501) -> 699915.06
A14: 2. Risk-Adjusted Return Metrics — Growth Bucket (Blended Glide-Path Returns, 2027–2032 pooled)
A16: Mean Annual Return | B16: =AVERAGE(Growth_MC!T2:Y501) -> 0.078446889
A17: Std Dev of Annual Return | B17: =STDEV(Growth_MC!T2:Y501) -> 0.17042701
A18: Sharpe Ratio | B18: =(B16-Assumptions!$B$16)/B17 -> 0.21972391 | C18: (Mean return − risk-free rate) / std dev of return
A19: Downside Deviation (target return = 0%) | B19: =SQRT(SUMPRODUCT((Growth_MC!T2:Y501<0)*((Growth_MC!T2:Y501)-0)^2)/COUNT(Growth_MC!T2:Y501)) -> 0.10414611
A20: Sortino Ratio | B20: =B16/B19 -> 0.75323879 | C20: Mean return / downside deviation — penalizes only bad-side volatility
A21: Value at Risk, 95% (1-yr, annual return) | B21: =-PERCENTILE(Growth_MC!T2:Y501,0.05) -> 0.27297477 | C21: Max loss not expected to be exceeded in 95% of years
A22: Conditional VaR / Expected Shortfall, 95% | B22: =-SUMPRODUCT((Growth_MC!T2:Y501<=PERCENTILE(Growth_MC!T2:Y501,0.05))*Growth_MC!T2:Y501)/SUMPRODUCT((Growth_MC!T2:Y501<=PERCENTILE(Growth_MC!T2:Y501,0.05))*1) -> 0.3755038 | C22: Average loss IN the worst 5% of years — how bad the tail actually is, not just its edge
A23: Average Max Drawdown (per simulated path) | B23: =AVERAGE(Growth_MC!AL2:AL501) -> -0.14824024
A24: Worst-Case Max Drawdown (5th pct. of paths) | B24: =PERCENTILE(Growth_MC!AL2:AL501,0.05) -> -0.49615121
A26: 3. Operating Reserve — Funding-Certainty Test (2033–2042, 10 payments of $50,000)
A28: Reserve Size Tested | B28: =Assumptions!$B$35 -> 441264
A29: Success Probability (all 10 payments funded, no shortfall) | B29: =AVERAGE(Reserve_MC!AH2:AH501) -> 0.96 | C29: This is the quantified meaning of “high degree of certainty.” Adjust the Reserve Cushion % on Assumptions to retest.
A31: 4. Facility Contribution — Recommended Range for Co-Sponsors (2033)
A33: Percentile | B33: Facility Contribution ($)
A34: 5th (downside) | B34: =PERCENTILE(Growth_MC!AM2:AM501,0.05) -> -179594.99
A35: 25th | B35: =PERCENTILE(Growth_MC!AM2:AM501,0.25) -> 36057.862
A36: 50th (Median) | B36: =PERCENTILE(Growth_MC!AM2:AM501,0.5) -> 264588.62
A37: 75th | B37: =PERCENTILE(Growth_MC!AM2:AM501,0.75) -> 456817.15
A38: 95th (upside) | B38: =PERCENTILE(Growth_MC!AM2:AM501,0.95) -> 752593.78
A39: Suggested communicated range | B39: =TEXT(MAX(B35,0),"$#,##0")&" – "&TEXT(B37,"$#,##0") -> $36,058 – $456,817
A40: Note: if the 25th-percentile figure above is negative, a below-average market could leave the 2033 portfolio unable to fully cover both the reserve and a facility contribution. The range above floors the low end at $0 for co-sponsor communication — state plainly that in an unfavorable scenario, the facility contribution could be $0.
A42: 5. Growth Path Over Time (for chart)
A44: Year | B44: P5 | C44: P25 | D44: P50 | E44: P75 | F44: P95
A45: 2027 | B45: =PERCENTILE(Growth_MC!Z2:Z501,0.05) -> 217036.95 | C45: =PERCENTILE(Growth_MC!Z2:Z501,0.25) -> 306369.84 | D45: =PERCENTILE(Growth_MC!Z2:Z501,0.5) -> 340164.13 | E45: =PERCENTILE(Growth_MC!Z2:Z501,0.75) -> 363134.88 | F45: =PERCENTILE(Growth_MC!Z2:Z501,0.95) -> 396477.33
A46: 2028 | B46: =PERCENTILE(Growth_MC!AA2:AA501,0.05) -> 304579.25 | C46: =PERCENTILE(Growth_MC!AA2:AA501,0.25) -> 467330.73 | D46: =PERCENTILE(Growth_MC!AA2:AA501,0.5) -> 548680.08 | E46: =PERCENTILE(Growth_MC!AA2:AA501,0.75) -> 594120.57 | F46: =PERCENTILE(Growth_MC!AA2:AA501,0.95) -> 672492.54
A47: 2029 | B47: =PERCENTILE(Growth_MC!AB2:AB501,0.05) -> 264312.09 | C47: =PERCENTILE(Growth_MC!AB2:AB501,0.25) -> 466502.73 | D47: =PERCENTILE(Growth_MC!AB2:AB501,0.5) -> 596182.48 | E47: =PERCENTILE(Growth_MC!AB2:AB501,0.75) -> 683197.52 | F47: =PERCENTILE(Growth_MC!AB2:AB501,0.95) -> 804050.78
A48: 2030 | B48: =PERCENTILE(Growth_MC!AC2:AC501,0.05) -> 238733.16 | C48: =PERCENTILE(Growth_MC!AC2:AC501,0.25) -> 446766.06 | D48: =PERCENTILE(Growth_MC!AC2:AC501,0.5) -> 636958.97 | E48: =PERCENTILE(Growth_MC!AC2:AC501,0.75) -> 765368.49 | F48: =PERCENTILE(Growth_MC!AC2:AC501,0.95) -> 925657.12
A49: 2031 | B49: =PERCENTILE(Growth_MC!AD2:AD501,0.05) -> 241155.04 | C49: =PERCENTILE(Growth_MC!AD2:AD501,0.25) -> 453220.15 | D49: =PERCENTILE(Growth_MC!AD2:AD501,0.5) -> 667634.29 | E49: =PERCENTILE(Growth_MC!AD2:AD501,0.75) -> 827514.1 | F49: =PERCENTILE(Growth_MC!AD2:AD501,0.95) -> 1095764.3
A50: 2032 | B50: =PERCENTILE(Growth_MC!AE2:AE501,0.05) -> 261669.01 | C50: =PERCENTILE(Growth_MC!AE2:AE501,0.25) -> 477321.86 | D50: =PERCENTILE(Growth_MC!AE2:AE501,0.5) -> 705852.61 | E50: =PERCENTILE(Growth_MC!AE2:AE501,0.75) -> 898081.15 | F50: =PERCENTILE(Growth_MC!AE2:AE501,0.95) -> 1193857.8
...

Sheet Assumptions
A1: Laura Gao Portfolio — Monte Carlo / Regime-Switching Model
A2: Assumptions & Key Inputs (edit blue cells to test alternative strategies)
A4: Market Regime Assumptions — Growth Bucket (Equities, 2027–2032)
A5: Bull Market: Annual Mean Return | B5: 0.16 | C5: Illustrative strong-regime equity return
A6: Bull Market: Annual Volatility (Std Dev) | B6: 0.1
A7: Bull Market: Persistence, P(Bull→Bull) | B7: 0.78 | C7: Bull regimes historically persist longer than bear regimes
A8: Bear Market: Annual Mean Return | B8: -0.12
A9: Bear Market: Annual Volatility (Std Dev) | B9: 0.2
A10: Bear Market: Persistence, P(Bear→Bear) | B10: 0.5
A11: Probability 2027 Starts in a Bull Regime | B11: 0.7
A13: Reserve / Fixed-Income Assumptions (Bond Sleeve, used in Reserve AND Glide Path)
A14: Bond Annual Mean Return | B14: 0.048 | C14: Source: 5-yr U.S. Treasury yield ≈4.8% (Sept 2026)
A15: Bond Annual Volatility (Std Dev) | B15: 0.03 | C15: Low-volatility, high-quality fixed income
A16: Risk-Free Rate (for Sharpe/Sortino) | B16: 0.041 | C16: Source: 3-month U.S. Treasury bill yield ≈4.1% (Sept 2026)
A18: Glide Path — Equity Weight by Year (De-risks the growth bucket before the 2033 reserve carve-out)
A19: Equity Weight, Year 1 (2027) | B19: 1 | C19: Weight in equities; remainder allocated to the bond sleeve above
A20: Equity Weight, Year 2 (2028) | B20: 1
A21: Equity Weight, Year 3 (2029) | B21: 1
A22: Equity Weight, Year 4 (2030) | B22: 1
A23: Equity Weight, Year 5 (2031) | B23: 0.8
A24: Equity Weight, Year 6 (2032) | B24: 0.6
A26: Cash Flow Schedule (from Client Case Study)
A27: Initial Contribution — Year 1 (2027) | B27: 300000 | C27: Per case study
A28: Additional Contribution — Year 2 (2028) | B28: 150000 | C28: Per case study
A29: Annual Operating Payment (2033–2042) | B29: 50000 | C29: Fixed, not inflation-adjusted, per case study
A30: Number of Operating Payments | B30: 10
A32: Operating Reserve Sizing
A33: PV of 10 Payments (Annuity-Due, discounted at Bond Return) | B33: =B29*(1-(1+B14)^-B30)/B14*(1+B14) -> 408577.77 | C33: Payments occur at the START of each year → annuity-due PV
A34: Reserve Cushion % | B34: 0.08 | C34: Tuned so the Reserve_MC tab shows ~94% funding-success probability
A35: Reserve Size to Test | B35: =B33*(1+B34) -> 441264 | C35: Feeds the Reserve_MC tab — flex the cushion % and re-check the success probability there
A37: Simulation Settings
A38: Number of Monte Carlo Trials | B38: 500

Sheet Growth_MC
A1: Trial | B1: Equity State Y1 (2027) | C1: Equity State Y2 (2028) | D1: Equity State Y3 (2029) | E1: Equity State Y4 (2030) | F1: Equity State Y5 (2031) | G1: Equity State Y6 (2032) | H1: Equity Return Y1 | I1: Equity Return Y2 | J1: Equity Return Y3 | K1: Equity Return Y4 | L1: Equity Return Y5 | M1: Equity Return Y6 | N1: Bond Sleeve Return Y1 | O1: Bond Sleeve Return Y2 | P1: Bond Sleeve Return Y3 | Q1: Bond Sleeve Return Y4 | R1: Bond Sleeve Return Y5 | S1: Bond Sleeve Return Y6 | T1: Blended Return Y1 (glide-weighted) | U1: Blended Return Y2 (glide-weighted) | V1: Blended Return Y3 (glide-weighted) | W1: Blended Return Y4 (glide-weighted) | X1: Blended Return Y5 (glide-weighted) | Y1: Blended Return Y6 (glide-weighted) | Z1: Value Y1 ($) | AA1: Value Y2 ($) | AB1: Value Y3 ($) | AC1: Value Y4 ($) | AD1: Value Y5 ($) | AE1: Value Y6 ($) | AF1: Peak Y1 ($) | AG1: Peak Y2 ($) | AH1: Peak Y3 ($) | AI1: Peak Y4 ($) | AJ1: Peak Y5 ($) | AK1: Peak Y6 ($) | AL1: Max Drawdown | AM1: Facility Contribution ($)
A2: =ROW()-1 -> 1 | B2: =IF(RAND()<Assumptions!$B$11,"Bull","Bear") -> Bull | C2: =IF(B2="Bull",IF(RAND()<Assumptions!$B$7,"Bull","Bear"),IF(RAND()<Assumptions!$B$10,"Bear","Bull")) -> Bull | D2: =IF(C2="Bull",IF(RAND()<Assumptions!$B$7,"Bull","Bear"),IF(RAND()<Assumptions!$B$10,"Bear","Bull")) -> Bull | E2: =IF(D2="Bull",IF(RAND()<Assumptions!$B$7,"Bull","Bear"),IF(RAND()<Assumptions!$B$10,"Bear","Bull")) -> Bear | F2: =IF(E2="Bull",IF(RAND()<Assumptions!$B$7,"Bull","Bear"),IF(RAND()<Assumptions!$B$10,"Bear","Bull")) -> Bull | G2: =IF(F2="Bull",IF(RAND()<Assumptions!$B$7,"Bull","Bear"),IF(RAND()<Assumptions!$B$10,"Bear","Bull")) -> Bull | H2: =IF(B2="Bull",NORMINV(RAND(),Assumptions!$B$5,Assumptions!$B$6),NORMINV(RAND(),Assumptions!$B$8,Assumptions!$B$9)) -> 0.24876587 | I2: =IF(C2="Bull",NORMINV(RAND(),Assumptions!$B$5,Assumptions!$B$6),NORMINV(RAND(),Assumptions!$B$8,Assumptions!$B$9)) -> 0.11013594 | J2: =IF(D2="Bull",NORMINV(RAND(),Assumptions!$B$5,Assumptions!$B$6),NORMINV(RAND(),Assumptions!$B$8,Assumptions!$B$9)) -> 0.29874802 | K2: =IF(E2="Bull",NORMINV(RAND(),Assumptions!$B$5,Assumptions!$B$6),NORMINV(RAND(),Assumptions!$B$8,Assumptions!$B$9)) -> -0.17244706 | L2: =IF(F2="Bull",NORMINV(RAND(),Assumptions!$B$5,Assumptions!$B$6),NORMINV(RAND(),Assumptions!$B$8,Assumptions!$B$9)) -> 0.29906656 | M2: =IF(G2="Bull",NORMINV(RAND(),Assumptions!$B$5,Assumptions!$B$6),NORMINV(RAND(),Assumptions!$B$8,Assumptions!$B$9)) -> 0.24278409 | N2: =NORMINV(RAND(),Assumptions!$B$14,Assumptions!$B$15) -> 0.022254018 | O2: =NORMINV(RAND(),Assumptions!$B$14,Assumptions!$B$15) -> 0.023215381 | P2: =NORMINV(RAND(),Assumptions!$B$14,Assumptions!$B$15) -> -0.0031806326 | Q2: =NORMINV(RAND(),Assumptions!$B$14,Assumptions!$B$15) -> 0.051680013 | R2: =NORMINV(RAND(),Assumptions!$B$14,Assumptions!$B$15) -> 0.027445921 | S2: =NORMINV(RAND(),Assumptions!$B$14,Assumptions!$B$15) -> 0.059777798 | T2: =Assumptions!$B$19*H2+(1-Assumptions!$B$19)*N2 -> 0.24876587 | U2: =Assumptions!$B$20*I2+(1-Assumptions!$B$20)*O2 -> 0.11013594 | V2: =Assumptions!$B$21*J2+(1-Assumptions!$B$21)*P2 -> 0.29874802 | W2: =Assumptions!$B$22*K2+(1-Assumptions!$B$22)*Q2 -> -0.17244706 | X2: =Assumptions!$B$23*L2+(1-Assumptions!$B$23)*R2 -> 0.24474243 | Y2: =Assumptions!$B$24*M2+(1-Assumptions!$B$24)*S2 -> 0.16958157 | Z2: =Assumptions!$B$27*(1+T2) -> 374629.76 | AA2: =(Z2+Assumptions!$B$28)*(1+U2) -> 582410.35 | AB2: =AA2*(1+V2) -> 756404.29 | AC2: =AB2*(1+W2) -> 625964.6 | AD2: =AC2*(1+X2) -> 779164.69 | AE2: =AD2*(1+Y2) -> 911296.67 | AF2: =Z2 -> 374629.76 | AG2: =MAX(AF2,AA2) -> 582410.35 | AH2: =MAX(AG2,AB2) -> 756404.29 | AI2: =MAX(AH2,AC2) -> 756404.29 | AJ2: =MAX(AI2,AD2) -> 779164.69 | AK2: =MAX(AJ2,AE2) -> 911296.67 | AL2: =MIN(Z2/AF2-1,AA2/AG2-1,AB2/AH2-1,AC2/AI2-1,AD2/AJ2-1,AE2/AK2-1) -> -0.17244706 | AM2: =AE2-Assumptions!$B$35 -> 470032.67
A3: =ROW()-1 -> 2 | B3: =IF(RAND()<Assumptions!$B$11,"Bull","Bear") -> Bull | C3: =IF(B3="Bull",IF(RAND()<Assumptions!$B$7,"Bull","Bear"),IF(RAND()<Assumptions!$B$10,"Bear","Bull")) -> Bull | D3: =IF(C3="Bull",IF(RAND()<Assumptions!$B$7,"Bull","Bear"),IF(RAND()<Assumptions!$B$10,"Bear","Bull")) -> Bear | E3: =IF(D3="Bull",IF(RAND()<Assumptions!$B$7,"Bull","Bear"),IF(RAND()<Assumptions!$B$10,"Bear","Bull")) -> Bear | F3: =IF(E3="Bull",IF(RAND()<Assumptions!$B$7,"Bull","Bear"),IF(RAND()<Assumptions!$B$10,"Bear","Bull")) -> Bear | G3: =IF(F3="Bull",IF(RAND()<Assumptions!$B$7,"Bull","Bear"),IF(RAND()<Assumptions!$B$10,"Bear","Bull")) -> Bear | H3: =IF(B3="Bull",NORMINV(RAND(),Assumptions!$B$5,Assumptions!$B$6),NORMINV(RAND(),Assumptions!$B$8,Assumptions!$B$9)) -> 0.062654669 | I3: =IF(C3="Bull",NORMINV(RAND(),Assumptions!$B$5,Assumptions!$B$6),NORMINV(RAND(),Assumptions!$B$8,Assumptions!$B$9)) -> 0.15018374 | J3: =IF(D3="Bull",NORMINV(RAND(),Assumptions!$B$5,Assumptions!$B$6),NORMINV(RAND(),Assumptions!$B$8,Assumptions!$B$9)) -> -0.20353242 | K3: =IF(E3="Bull",NORMINV(RAND(),Assumptions!$B$5,Assumptions!$B$6),NORMINV(RAND(),Assumptions!$B$8,Assumptions!$B$9)) -> 0.049966644 | L3: =IF(F3="Bull",NORMINV(RAND(),Assumptions!$B$5,Assumptions!$B$6),NORMINV(RAND(),Assumptions!$B$8,Assumptions!$B$9)) -> -0.21009469 | M3: =IF(G3="Bull",NORMINV(RAND(),Assumptions!$B$5,Assumptions!$B$6),NORMINV(RAND(),Assumptions!$B$8,Assumptions!$B$9)) -> -0.25608094 | N3: =NORMINV(RAND(),Assumptions!$B$14,Assumptions!$B$15) -> 0.038902622 | O3: =NORMINV(RAND(),Assumptions!$B$14,Assumptions!$B$15) -> 0.097968964 | P3: =NORMINV(RAND(),Assumptions!$B$14,Assumptions!$B$15) -> 0.056447876 | Q3: =NORMINV(RAND(),Assumptions!$B$14,Assumptions!$B$15) -> 0.04695177 | R3: =NORMINV(RAND(),Assumptions!$B$14,Assumptions!$B$15) -> 0.063529888 | S3: =NORMINV(RAND(),Assumptions!$B$14,Assumptions!$B$15) -> 0.083244225 | T3: =Assumptions!$B$19*H3+(1-Assumptions!$B$19)*N3 -> 0.062654669 | U3: =Assumptions!$B$20*I3+(1-Assumptions!$B$20)*O3 -> 0.15018374 | V3: =Assumptions!$B$21*J3+(1-Assumptions!$B$21)*P3 -> -0.20353242 | W3: =Assumptions!$B$22*K3+(1-Assumptions!$B$22)*Q3 -> 0.049966644 | X3: =Assumptions!$B$23*L3+(1-Assumptions!$B$23)*R3 -> -0.15536978 | Y3: =Assumptions!$B$24*M3+(1-Assumptions!$B$24)*S3 -> -0.12035087 | Z3: =Assumptions!$B$27*(1+T3) -> 318796.4 | AA3: =(Z3+Assumptions!$B$28)*(1+U3) -> 539202 | AB3: =AA3*(1+V3) -> 429456.91 | AC3: =AB3*(1+W3) -> 450915.43 | AD3: =AC3*(1+X3) -> 380856.8 | AE3: =AD3*(1+Y3) -> 335020.35 | AF3: =Z3 -> 318796.4 | AG3: =MAX(AF3,AA3) -> 539202 | AH3: =MAX(AG3,AB3) -> 539202 | AI3: =MAX(AH3,AC3) -> 539202 | AJ3: =MAX(AI3,AD3) -> 539202 | AK3: =MAX(AJ3,AE3) -> 539202 | AL3: =MIN(Z3/AF3-1,AA3/AG3-1,AB3/AH3-1,AC3/AI3-1,AD3/AJ3-1,AE3/AK3-1) -> -0.37867375 | AM3: =AE3-Assumptions!$B$35 -> -106243.64
A4: =ROW()-1 -> 3 | B4: =IF(RAND()<Assumptions!$B$11,"Bull","Bear") -> Bull | C4: =IF(B4="Bull",IF(RAND()<Assumptions!$B$7,"Bull","Bear"),IF(RAND()<Assumptions!$B$10,"Bear","Bull")) -> Bull | D4: =IF(C4="Bull",IF(RAND()<Assumptions!$B$7,"Bull","Bear"),IF(RAND()<Assumptions!$B$10,"Bear","Bull")) -> Bull | E4: =IF(D4="Bull",IF(RAND()<Assumptions!$B$7,"Bull","Bear"),IF(RAND()<Assumptions!$B$10,"Bear","Bull")) -> Bear | F4: =IF(E4="Bull",IF(RAND()<Assumptions!$B$7,"Bull","Bear"),IF(RAND()<Assumptions!$B$10,"Bear","Bull")) -> Bear | G4: =IF(F4="Bull",IF(RAND()<Assumptions!$B$7,"Bull","Bear"),IF(RAND()<Assumptions!$B$10,"Bear","Bull")) -> Bear | H4: =IF(B4="Bull",NORMINV(RAND(),Assumptions!$B$5,Assumptions!$B$6),NORMINV(RAND(),Assumptions!$B$8,Assumptions!$B$9)) -> 0.1395777 | I4: =IF(C4="Bull",NORMINV(RAND(),Assumptions!$B$5,Assumptions!$B$6),NORMINV(RAND(),Assumptions!$B$8,Assumptions!$B$9)) -> 0.14467711 | J4: =IF(D4="Bull",NORMINV(RAND(),Assumptions!$B$5,Assumptions!$B$6),NORMINV(RAND(),Assumptions!$B$8,Assumptions!$B$9)) -> 0.13295531 | K4: =IF(E4="Bull",NORMINV(RAND(),Assumptions!$B$5,Assumptions!$B$6),NORMINV(RAND(),Assumptions!$B$8,Assumptions!$B$9)) -> -0.027113039 | L4: =IF(F4="Bull",NORMINV(RAND(),Assumptions!$B$5,Assumptions!$B$6),NORMINV(RAND(),Assumptions!$B$8,Assumptions!$B$9)) -> -0.11766143 | M4: =IF(G4="Bull",NORMINV(RAND(),Assumptions!$B$5,Assumptions!$B$6),NORMINV(RAND(),Assumptions!$B$8,Assumptions!$B$9)) -> -0.14592371 | N4: =NORMINV(RAND(),Assumptions!$B$14,Assumptions!$B$15) -> 0.032519574 | O4: =NORMINV(RAND(),Assumptions!$B$14,Assumptions!$B$15) -> 0.057469786 | P4: =NORMINV(RAND(),Assumptions!$B$14,Assumptions!$B$15) -> 0.047577289 | Q4: =NORMINV(RAND(),Assumptions!$B$14,Assumptions!$B$15) -> 0.037331532 | R4: =NORMINV(RAND(),Assumptions!$B$14,Assumptions!$B$15) -> 0.10225534 | S4: =NORMINV(RAND(),Assumptions!$B$14,Assumptions!$B$15) -> 0.064759549 | T4: =Assumptions!$B$19*H4+(1-Assumptions!$B$19)*N4 -> 0.1395777 | U4: =Assumptions!$B$20*I4+(1-Assumptions!$B$20)*O4 -> 0.14467711 | V4: =Assumptions!$B$21*J4+(1-Assumptions!$B$21)*P4 -> 0.13295531 | W4: =Assumptions!$B$22*K4+(1-Assumptions!$B$22)*Q4 -> -0.027113039 | X4: =Assumptions!$B$23*L4+(1-Assumptions!$B$23)*R4 -> -0.073678077 | Y4: =Assumptions!$B$24*M4+(1-Assumptions!$B$24)*S4 -> -0.061650408 | Z4: =Assumptions!$B$27*(1+T4) -> 341873.31 | AA4: =(Z4+Assumptions!$B$28)*(1+U4) -> 563036.12 | AB4: =AA4*(1+V4) -> 637894.76 | AC4: =AB4*(1+W4) -> 620599.49 | AD4: =AC4*(1+X4) -> 574874.92 | AE4: =AD4*(1+Y4) -> 539433.64 | AF4: =Z4 -> 341873.31 | AG4: =MAX(AF4,AA4) -> 563036.12 | AH4: =MAX(AG4,AB4) -> 637894.76 | AI4: =MAX(AH4,AC4) -> 637894.76 | AJ4: =MAX(AI4,AD4) -> 637894.76 | AK4: =MAX(AJ4,AE4) -> 637894.76 | AL4: =MIN(Z4/AF4-1,AA4/AG4-1,AB4/AH4-1,AC4/AI4-1,AD4/AJ4-1,AE4/AK4-1) -> -0.15435323 | AM4: =AE4-Assumptions!$B$35 -> 98169.646
A5: =ROW()-1 -> 4 | B5: =IF(RAND()<Assumptions!$B$11,"Bull","Bear") -> Bear | C5: =IF(B5="Bull",IF(RAND()<Assumptions!$B$7,"Bull","Bear"),IF(RAND()<Assumptions!$B$10,"Bear","Bull")) -> Bear | D5: =IF(C5="Bull",IF(RAND()<Assumptions!$B$7,"Bull","Bear"),IF(RAND()<Assumptions!$B$10,"Bear","Bull")) -> Bull | E5: =IF(D5="Bull",IF(RAND()<Assumptions!$B$7,"Bull","Bear"),IF(RAND()<Assumptions!$B$10,"Bear","Bull")) -> Bull | F5: =IF(E5="Bull",IF(RAND()<Assumptions!$B$7,"Bull","Bear"),IF(RAND()<Assumptions!$B$10,"Bear","Bull")) -> Bull | G5: =IF(F5="Bull",IF(RAND()<Assumptions!$B$7,"Bull","Bear"),IF(RAND()<Assumptions!$B$10,"Bear","Bull")) -> Bull | H5: =IF(B5="Bull",NORMINV(RAND(),Assumptions!$B$5,Assumptions!$B$6),NORMINV(RAND(),Assumptions!$B$8,Assumptions!$B$9)) -> 0.17432051 | I5: =IF(C5="Bull",NORMINV(RAND(),Assumptions!$B$5,Assumptions!$B$6),NORMINV(RAND(),Assumptions!$B$8,Assumptions!$B$9)) -> 0.11317244 | J5: =IF(D5="Bull",NORMINV(RAND(),Assumptions!$B$5,Assumptions!$B$6),NORMINV(RAND(),Assumptions!$B$8,Assumptions!$B$9)) -> 0.071664394 | K5: =IF(E5="Bull",NORMINV(RAND(),Assumptions!$B$5,Assumptions!$B$6),NORMINV(RAND(),Assumptions!$B$8,Assumptions!$B$9)) -> 0.13011022 | L5: =IF(F5="Bull",NORMINV(RAND(),Assumptions!$B$5,Assumptions!$B$6),NORMINV(RAND(),Assumptions!$B$8,Assumptions!$B$9)) -> 0.15055526 | M5: =IF(G5="Bull",NORMINV(RAND(),Assumptions!$B$5,Assumptions!$B$6),NORMINV(RAND(),Assumptions!$B$8,Assumptions!$B$9)) -> 0.29976317 | N5: =NORMINV(RAND(),Assumptions!$B$14,Assumptions!$B$15) -> 0.047212398 | O5: =NORMINV(RAND(),Assumptions!$B$14,Assumptions!$B$15) -> 0.050740133 | P5: =NORMINV(RAND(),Assumptions!$B$14,Assumptions!$B$15) -> 0.060743602 | Q5: =NORMINV(RAND(),Assumptions!$B$14,Assumptions!$B$15) -> 0.032825126 | R5: =NORMINV(RAND(),Assumptions!$B$14,Assumptions!$B$15) -> 0.028162547 | S5: =NORMINV(RAND(),Assumptions!$B$14,Assumptions!$B$15) -> 0.085062436 | T5: =Assumptions!$B$19*H5+(1-Assumptions!$B$19)*N5 -> 0.17432051 | U5: =Assumptions!$B$20*I5+(1-Assumptions!$B$20)*O5 -> 0.11317244 | V5: =Assumptions!$B$21*J5+(1-Assumptions!$B$21)*P5 -> 0.071664394 | W5: =Assumptions!$B$22*K5+(1-Assumptions!$B$22)*Q5 -> 0.13011022 | X5: =Assumptions!$B$23*L5+(1-Assumptions!$B$23)*R5 -> 0.12607672 | Y5: =Assumptions!$B$24*M5+(1-Assumptions!$B$24)*S5 -> 0.21388288 | Z5: =Assumptions!$B$27*(1+T5) -> 352296.15 | AA5: =(Z5+Assumptions!$B$28)*(1+U5) -> 559142.23 | AB5: =AA5*(1+V5) -> 599212.82 | AC5: =AB5*(1+W5) -> 677176.53 | AD5: =AC5*(1+X5) -> 762552.73 | AE5: =AD5*(1+Y5) -> 925649.7 | AF5: =Z5 -> 352296.15 | AG5: =MAX(AF5,AA5) -> 559142.23 | AH5: =MAX(AG5,AB5) -> 599212.82 | AI5: =MAX(AH5,AC5) -> 677176.53 | AJ5: =MAX(AI5,AD5) -> 762552.73 | AK5: =MAX(AJ5,AE5) -> 925649.7 | AL5: =MIN(Z5/AF5-1,AA5/AG5-1,AB5/AH5-1,AC5/AI5-1,AD5/AJ5-1,AE5/AK5-1) -> 0 | AM5: =AE5-Assumptions!$B$35 -> 484385.7
A6: =ROW()-1 -> 5 | B6: =IF(RAND()<Assumptions!$B$11,"Bull","Bear") -> Bull | C6: =IF(B6="Bull",IF(RAND()<Assumptions!$B$7,"Bull","Bear"),IF(RAND()<Assumptions!$B$10,"Bear","Bull")) -> Bull | D6: =IF(C6="Bull",IF(RAND()<Assumptions!$B$7,"Bull","Bear"),IF(RAND()<Assumptions!$B$10,"Bear","Bull")) -> Bull | E6: =IF(D6="Bull",IF(RAND()<Assumptions!$B$7,"Bull","Bear"),IF(RAND()<Assumptions!$B$10,"Bear","Bull")) -> Bull | F6: =IF(E6="Bull",IF(RAND()<Assumptions!$B$7,"Bull","Bear"),IF(RAND()<Assumptions!$B$10,"Bear","Bull")) -> Bull | G6: =IF(F6="Bull",IF(RAND()<Assumptions!$B$7,"Bull","Bear"),IF(RAND()<Assumptions!$B$10,"Bear","Bull")) -> Bull | H6: =IF(B6="Bull",NORMINV(RAND(),Assumptions!$B$5,Assumptions!$B$6),NORMINV(RAND(),Assumptions!$B$8,Assumptions!$B$9)) -> 0.18881852 | I6: =IF(C6="Bull",NORMINV(RAND(),Assumptions!$B$5,Assumptions!$B$6),NORMINV(RAND(),Assumptions!$B$8,Assumptions!$B$9)) -> 0.038755855 | J6: =IF(D6="Bull",NORMINV(RAND(),Assumptions!$B$5,Assumptions!$B$6),NORMINV(RAND(),Assumptions!$B$8,Assumptions!$B$9)) -> 0.21739594 | K6: =IF(E6="Bull",NORMINV(RAND(),Assumptions!$B$5,Assumptions!$B$6),NORMINV(RAND(),Assumptions!$B$8,Assumptions!$B$9)) -> 0.21872873 | L6: =IF(F6="Bull",NORMINV(RAND(),Assumptions!$B$5,Assumptions!$B$6),NORMINV(RAND(),Assumptions!$B$8,Assumptions!$B$9)) -> 0.11976064 | M6: =IF(G6="Bull",NORMINV(RAND(),Assumptions!$B$5,Assumptions!$B$6),NORMINV(RAND(),Assumptions!$B$8,Assumptions!$B$9)) -> 0.14706463 | N6: =NORMINV(RAND(),Assumptions!$B$14,Assumptions!$B$15) -> 0.079671986 | O6: =NORMINV(RAND(),Assumptions!$B$14,Assumptions!$B$15) -> 0.054262191 | P6: =NORMINV(RAND(),Assumptions!$B$14,Assumptions!$B$15) -> 0.040106505 | Q6: =NORMINV(RAND(),Assumptions!$B$14,Assumptions!$B$15) -> 0.040886568 | R6: =NORMINV(RAND(),Assumptions!$B$14,Assumptions!$B$15) -> 0.043604229 | S6: =NORMINV(RAND(),Assumptions!$B$14,Assumptions!$B$15) -> 0.031491836 | T6: =Assumptions!$B$19*H6+(1-Assumptions!$B$19)*N6 -> 0.18881852 | U6: =Assumptions!$B$20*I6+(1-Assumptions!$B$20)*O6 -> 0.038755855 | V6: =Assumptions!$B$21*J6+(1-Assumptions!$B$21)*P6 -> 0.21739594 | W6: =Assumptions!$B$22*K6+(1-Assumptions!$B$22)*Q6 -> 0.21872873 | X6: =Assumptions!$B$23*L6+(1-Assumptions!$B$23)*R6 -> 0.10452936 | Y6: =Assumptions!$B$24*M6+(1-Assumptions!$B$24)*S6 -> 0.10083551 | Z6: =Assumptions!$B$27*(1+T6) -> 356645.56 | AA6: =(Z6+Assumptions!$B$28)*(1+U6) -> 526281.04 | AB6: =AA6*(1+V6) -> 640692.4 | AC6: =AB6*(1+W6) -> 780830.23 | AD6: =AC6*(1+X6) -> 862449.92 | AE6: =AD6*(1+Y6) -> 949415.5 | AF6: =Z6 -> 356645.56 | AG6: =MAX(AF6,AA6) -> 526281.04 | AH6: =MAX(AG6,AB6) -> 640692.4 | AI6: =MAX(AH6,AC6) -> 780830.23 | AJ6: =MAX(AI6,AD6) -> 862449.92 | AK6: =MAX(AJ6,AE6) -> 949415.5 | AL6: =MIN(Z6/AF6-1,AA6/AG6-1,AB6/AH6-1,AC6/AI6-1,AD6/AJ6-1,AE6/AK6-1) -> 0 | AM6: =AE6-Assumptions!$B$35 -> 508151.5
A7: =ROW()-1 -> 6 | B7: =IF(RAND()<Assumptions!$B$11,"Bull","Bear") -> Bull | C7: =IF(B7="Bull",IF(RAND()<Assumptions!$B$7,"Bull","Bear"),IF(RAND()<Assumptions!$B$10,"Bear","Bull")) -> Bull | D7: =IF(C7="Bull",IF(RAND()<Assumptions!$B$7,"Bull","Bear"),IF(RAND()<Assumptions!$B$10,"Bear","Bull")) -> Bull | E7: =IF(D7="Bull",IF(RAND()<Assumptions!$B$7,"Bull","Bear"),IF(RAND()<Assumptions!$B$10,"Bear","Bull")) -> Bull | F7: =IF(E7="Bull",IF(RAND()<Assumptions!$B$7,"Bull","Bear"),IF(RAND()<Assumptions!$B$10,"Bear","Bull")) -> Bull | G7: =IF(F7="Bull",IF(RAND()<Assumptions!$B$7,"Bull","Bear"),IF(RAND()<Assumptions!$B$10,"Bear","Bull")) -> Bull | H7: =IF(B7="Bull",NORMINV(RAND(),Assumptions!$B$5,Assumptions!$B$6),NORMINV(RAND(),Assumptions!$B$8,Assumptions!$B$9)) -> 0.093150432 | I7: =IF(C7="Bull",NORMINV(RAND(),Assumptions!$B$5,Assumptions!$B$6),NORMINV(RAND(),Assumptions!$B$8,Assumptions!$B$9)) -> 0.042419221 | J7: =IF(D7="Bull",NORMINV(RAND(),Assumptions!$B$5,Assumptions!$B$6),NORMINV(RAND(),Assumptions!$B$8,Assumptions!$B$9)) -> 0.025371763 | K7: =IF(E7="Bull",NORMINV(RAND(),Assumptions!$B$5,Assumptions!$B$6),NORMINV(RAND(),Assumptions!$B$8,Assumptions!$B$9)) -> 0.23161731 | L7: =IF(F7="Bull",NORMINV(RAND(),Assumptions!$B$5,Assumptions!$B$6),NORMINV(RAND(),Assumptions!$B$8,Assumptions!$B$9)) -> 0.12229323 | M7: =IF(G7="Bull",NORMINV(RAND(),Assumptions!$B$5,Assumptions!$B$6),NORMINV(RAND(),Assumptions!$B$8,Assumptions!$B$9)) -> 0.27681921 | N7: =NORMINV(RAND(),Assumptions!$B$14,Assumptions!$B$15) -> 0.017443395 | O7: =NORMINV(RAND(),Assumptions!$B$14,Assumptions!$B$15) -> -0.01420326 | P7: =NORMINV(RAND(),Assumptions!$B$14,Assumptions!$B$15) -> 0.066916686 | Q7: =NORMINV(RAND(),Assumptions!$B$14,Assumptions!$B$15) -> 0.019451465 | R7: =NORMINV(RAND(),Assumptions!$B$14,Assumptions!$B$15) -> 0.00047327016 | S7: =NORMINV(RAND(),Assumptions!$B$14,Assumptions!$B$15) -> 0.0050733886 | T7: =Assumptions!$B$19*H7+(1-Assumptions!$B$19)*N7 -> 0.093150432 | U7: =Assumptions!$B$20*I7+(1-Assumptions!$B$20)*O7 -> 0.042419221 | V7: =Assumptions!$B$21*J7+(1-Assumptions!$B$21)*P7 -> 0.025371763 | W7: =Assumptions!$B$22*K7+(1-Assumptions!$B$22)*Q7 -> 0.23161731 | X7: =Assumptions!$B$23*L7+(1-Assumptions!$B$23)*R7 -> 0.097929236 | Y7: =Assumptions!$B$24*M7+(1-Assumptions!$B$24)*S7 -> 0.16812088 | Z7: =Assumptions!$B$27*(1+T7) -> 327945.13 | AA7: =(Z7+Assumptions!$B$28)*(1+U7) -> 498219.19 | AB7: =AA7*(1+V7) -> 510859.89 | AC7: =AB7*(1+W7) -> 629183.88 | AD7: =AC7*(1+X7) -> 690799.38 | AE7: =AD7*(1+Y7) -> 806937.18 | AF7: =Z7 -> 327945.13 | AG7: =MAX(AF7,AA7) -> 498219.19 | AH7: =MAX(AG7,AB7) -> 510859.89 | AI7: =MAX(AH7,AC7) -> 629183.88 | AJ7: =MAX(AI7,AD7) -> 690799.38 | AK7: =MAX(AJ7,AE7) -> 806937.18 | AL7: =MIN(Z7/AF7-1,AA7/AG7-1,AB7/AH7-1,AC7/AI7-1,AD7/AJ7-1,AE7/AK7-1) -> 0 | AM7: =AE7-Assumptions!$B$35 -> 365673.18
A8: =ROW()-1 -> 7 | B8: =IF(RAND()<Assumptions!$B$11,"Bull","Bear") -> Bear | C8: =IF(B8="Bull",IF(RAND()<Assumptions!$B$7,"Bull","Bear"),IF(RAND()<Assumptions!$B$10,"Bear","Bull")) -> Bear | D8: =IF(C8="Bull",IF(RAND()<Assumptions!$B$7,"Bull","Bear"),IF(RAND()<Assumptions!$B$10,"Bear","Bull")) -> Bear | E8: =IF(D8="Bull",IF(RAND()<Assumptions!$B$7,"Bull","Bear"),IF(RAND()<Assumptions!$B$10,"Bear","Bull")) -> Bear | F8: =IF(E8="Bull",IF(RAND()<Assumptions!$B$7,"Bull","Bear"),IF(RAND()<Assumptions!$B$10,"Bear","Bull")) -> Bear | G8: =IF(F8="Bull",IF(RAND()<Assumptions!$B$7,"Bull","Bear"),IF(RAND()<Assumptions!$B$10,"Bear","Bull")) -> Bear | H8: =IF(B8="Bull",NORMINV(RAND(),Assumptions!$B$5,Assumptions!$B$6),NORMINV(RAND(),Assumptions!$B$8,Assumptions!$B$9)) -> -0.023824901 | I8: =IF(C8="Bull",NORMINV(RAND(),Assumptions!$B$5,Assumptions!$B$6),NORMINV(RAND(),Assumptions!$B$8,Assumptions!$B$9)) -> 0.056893933 | J8: =IF(D8="Bull",NORMINV(RAND(),Assumptions!$B$5,Assumptions!$B$6),NORMINV(RAND(),Assumptions!$B$8,Assumptions!$B$9)) -> -0.35313865 | K8: =IF(E8="Bull",NORMINV(RAND(),Assumptions!$B$5,Assumptions!$B$6),NORMINV(RAND(),Assumptions!$B$8,Assumptions!$B$9)) -> -1.6108222e-05 | L8: =IF(F8="Bull",NORMINV(RAND(),Assumptions!$B$5,Assumptions!$B$6),NORMINV(RAND(),Assumptions!$B$8,Assumptions!$B$9)) -> -0.25623441 | M8: =IF(G8="Bull",NORMINV(RAND(),Assumptions!$B$5,Assumptions!$B$6),NORMINV(RAND(),Assumptions!$B$8,Assumptions!$B$9)) -> 0.086985024 | N8: =NORMINV(RAND(),Assumptions!$B$14,Assumptions!$B$15) -> 0.046298033 | O8: =NORMINV(RAND(),Assumptions!$B$14,Assumptions!$B$15) -> 0.094033526 | P8: =NORMINV(RAND(),Assumptions!$B$14,Assumptions!$B$15) -> 0.05277491 | Q8: =NORMINV(RAND(),Assumptions!$B$14,Assumptions!$B$15) -> 0.027210495 | R8: =NORMINV(RAND(),Assumptions!$B$14,Assumptions!$B$15) -> 0.004037683 | S8: =NORMINV(RAND(),Assumptions!$B$14,Assumptions!$B$15) -> 0.010346183 | T8: =Assumptions!$B$19*H8+(1-Assumptions!$B$19)*N8 -> -0.023824901 | U8: =Assumptions!$B$20*I8+(1-Assumptions!$B$20)*O8 -> 0.056893933 | V8: =Assumptions!$B$21*J8+(1-Assumptions!$B$21)*P8 -> -0.35313865 | W8: =Assumptions!$B$22*K8+(1-Assumptions!$B$22)*Q8 -> -1.6108222e-05 | X8: =Assumptions!$B$23*L8+(1-Assumptions!$B$23)*R8 -> -0.20417999 | Y8: =Assumptions!$B$24*M8+(1-Assumptions!$B$24)*S8 -> 0.056329488 | Z8: =Assumptions!$B$27*(1+T8) -> 292852.53 | AA8: =(Z8+Assumptions!$B$28)*(1+U8) -> 468048.15 | AB8: =AA8*(1+V8) -> 302762.26 | AC8: =AB8*(1+W8) -> 302757.38 | AD8: =AC8*(1+X8) -> 240940.38 | AE8: =AD8*(1+Y8) -> 254512.43 | AF8: =Z8 -> 292852.53 | AG8: =MAX(AF8,AA8) -> 468048.15 | AH8: =MAX(AG8,AB8) -> 468048.15 | AI8: =MAX(AH8,AC8) -> 468048.15 | AJ8: =MAX(AI8,AD8) -> 468048.15 | AK8: =MAX(AJ8,AE8) -> 468048.15 | AL8: =MIN(Z8/AF8-1,AA8/AG8-1,AB8/AH8-1,AC8/AI8-1,AD8/AJ8-1,AE8/AK8-1) -> -0.48522309 | AM8: =AE8-Assumptions!$B$35 -> -186751.57
A9: =ROW()-1 -> 8 | B9: =IF(RAND()<Assumptions!$B$11,"Bull","Bear") -> Bull | C9: =IF(B9="Bull",IF(RAND()<Assumptions!$B$7,"Bull","Bear"),IF(RAND()<Assumptions!$B$10,"Bear","Bull")) -> Bull | D9: =IF(C9="Bull",IF(RAND()<Assumptions!$B$7,"Bull","Bear"),IF(RAND()<Assumptions!$B$10,"Bear","Bull")) -> Bull | E9: =IF(D9="Bull",IF(RAND()<Assumptions!$B$7,"Bull","Bear"),IF(RAND()<Assumptions!$B$10,"Bear","Bull")) -> Bear | F9: =IF(E9="Bull",IF(RAND()<Assumptions!$B$7,"Bull","Bear"),IF(RAND()<Assumptions!$B$10,"Bear","Bull")) -> Bull | G9: =IF(F9="Bull",IF(RAND()<Assumptions!$B$7,"Bull","Bear"),IF(RAND()<Assumptions!$B$10,"Bear","Bull")) -> Bull | H9: =IF(B9="Bull",NORMINV(RAND(),Assumptions!$B$5,Assumptions!$B$6),NORMINV(RAND(),Assumptions!$B$8,Assumptions!$B$9)) -> 0.10367254 | I9: =IF(C9="Bull",NORMINV(RAND(),Assumptions!$B$5,Assumptions!$B$6),NORMINV(RAND(),Assumptions!$B$8,Assumptions!$B$9)) -> 0.22315465 | J9: =IF(D9="Bull",NORMINV(RAND(),Assumptions!$B$5,Assumptions!$B$6),NORMINV(RAND(),Assumptions!$B$8,Assumptions!$B$9)) -> 0.25837517 | K9: =IF(E9="Bull",NORMINV(RAND(),Assumptions!$B$5,Assumptions!$B$6),NORMINV(RAND(),Assumptions!$B$8,Assumptions!$B$9)) -> -0.22502201 | L9: =IF(F9="Bull",NORMINV(RAND(),Assumptions!$B$5,Assumptions!$B$6),NORMINV(RAND(),Assumptions!$B$8,Assumptions!$B$9)) -> 0.26923783 | M9: =IF(G9="Bull",NORMINV(RAND(),Assumptions!$B$5,Assumptions!$B$6),NORMINV(RAND(),Assumptions!$B$8,Assumptions!$B$9)) -> 0.18610223 | N9: =NORMINV(RAND(),Assumptions!$B$14,Assumptions!$B$15) -> 0.048847454 | O9: =NORMINV(RAND(),Assumptions!$B$14,Assumptions!$B$15) -> 0.0075743897 | P9: =NORMINV(RAND(),Assumptions!$B$14,Assumptions!$B$15) -> 0.043826282 | Q9: =NORMINV(RAND(),Assumptions!$B$14,Assumptions!$B$15) -> 0.069490378 | R9: =NORMINV(RAND(),Assumptions!$B$14,Assumptions!$B$15) -> 0.054806273 | S9: =NORMINV(RAND(),Assumptions!$B$14,Assumptions!$B$15) -> 0.025351123 | T9: =Assumptions!$B$19*H9+(1-Assumptions!$B$19)*N9 -> 0.10367254 | U9: =Assumptions!$B$20*I9+(1-Assumptions!$B$20)*O9 -> 0.22315465 | V9: =Assumptions!$B$21*J9+(1-Assumptions!$B$21)*P9 -> 0.25837517 | W9: =Assumptions!$B$22*K9+(1-Assumptions!$B$22)*Q9 -> -0.22502201 | X9: =Assumptions!$B$23*L9+(1-Assumptions!$B$23)*R9 -> 0.22635152 | Y9: =Assumptions!$B$24*M9+(1-Assumptions!$B$24)*S9 -> 0.12180179 | Z9: =Assumptions!$B$27*(1+T9) -> 331101.76 | AA9: =(Z9+Assumptions!$B$28)*(1+U9) -> 588461.86 | AB9: =AA9*(1+V9) -> 740505.79 | AC9: =AB9*(1+W9) -> 573875.69 | AD9: =AC9*(1+X9) -> 703773.32 | AE9: =AD9*(1+Y9) -> 789494.17 | AF9: =Z9 -> 331101.76 | AG9: =MAX(AF9,AA9) -> 588461.86 | AH9: =MAX(AG9,AB9) -> 740505.79 | AI9: =MAX(AH9,AC9) -> 740505.79 | AJ9: =MAX(AI9,AD9) -> 740505.79 | AK9: =MAX(AJ9,AE9) -> 789494.17 | AL9: =MIN(Z9/AF9-1,AA9/AG9-1,AB9/AH9-1,AC9/AI9-1,AD9/AJ9-1,AE9/AK9-1) -> -0.22502201 | AM9: =AE9-Assumptions!$B$35 -> 348230.17
A10: =ROW()-1 -> 9 | B10: =IF(RAND()<Assumptions!$B$11,"Bull","Bear") -> Bull | C10: =IF(B10="Bull",IF(RAND()<Assumptions!$B$7,"Bull","Bear"),IF(RAND()<Assumptions!$B$10,"Bear","Bull")) -> Bull | D10: =IF(C10="Bull",IF(RAND()<Assumptions!$B$7,"Bull","Bear"),IF(RAND()<Assumptions!$B$10,"Bear","Bull")) -> Bull | E10: =IF(D10="Bull",IF(RAND()<Assumptions!$B$7,"Bull","Bear"),IF(RAND()<Assumptions!$B$10,"Bear","Bull")) -> Bear | F10: =IF(E10="Bull",IF(RAND()<Assumptions!$B$7,"Bull","Bear"),IF(RAND()<Assumptions!$B$10,"Bear","Bull")) -> Bull | G10: =IF(F10="Bull",IF(RAND()<Assumptions!$B$7,"Bull","Bear"),IF(RAND()<Assumptions!$B$10,"Bear","Bull")) -> Bull | H10: =IF(B10="Bull",NORMINV(RAND(),Assumptions!$B$5,Assumptions!$B$6),NORMINV(RAND(),Assumptions!$B$8,Assumptions!$B$9)) -> 0.20122498 | I10: =IF(C10="Bull",NORMINV(RAND(),Assumptions!$B$5,Assumptions!$B$6),NORMINV(RAND(),Assumptions!$B$8,Assumptions!$B$9)) -> 0.1199536 | J10: =IF(D10="Bull",NORMINV(RAND(),Assumptions!$B$5,Assumptions!$B$6),NORMINV(RAND(),Assumptions!$B$8,Assumptions!$B$9)) -> 0.13282396 | K10: =IF(E10="Bull",NORMINV(RAND(),Assumptions!$B$5,Assumptions!$B$6),NORMINV(RAND(),Assumptions!$B$8,Assumptions!$B$9)) -> 0.11529598 | L10: =IF(F10="Bull",NORMINV(RAND(),Assumptions!$B$5,Assumptions!$B$6),NORMINV(RAND(),Assumptions!$B$8,Assumptions!$B$9)) -> 0.097568518 | M10: =IF(G10="Bull",NORMINV(RAND(),Assumptions!$B$5,Assumptions!$B$6),NORMINV(RAND(),Assumptions!$B$8,Assumptions!$B$9)) -> 0.18637672 | N10: =NORMINV(RAND(),Assumptions!$B$14,Assumptions!$B$15) -> 0.051295357 | O10: =NORMINV(RAND(),Assumptions!$B$14,Assumptions!$B$15) -> 0.049134561 | P10: =NORMINV(RAND(),Assumptions!$B$14,Assumptions!$B$15) -> 0.076086356 | Q10: =NORMINV(RAND(),Assumptions!$B$14,Assumptions!$B$15) -> 0.022932223 | R10: =NORMINV(RAND(),Assumptions!$B$14,Assumptions!$B$15) -> 0.0083747472 | S10: =NORMINV(RAND(),Assumptions!$B$14,Assumptions!$B$15) -> 0.053089042 | T10: =Assumptions!$B$19*H10+(1-Assumptions!$B$19)*N10 -> 0.20122498 | U10: =Assumptions!$B$20*I10+(1-Assumptions!$B$20)*O10 -> 0.1199536 | V10: =Assumptions!$B$21*J10+(1-Assumptions!$B$21)*P10 -> 0.13282396 | W10: =Assumptions!$B$22*K10+(1-Assumptions!$B$22)*Q10 -> 0.11529598 | X10: =Assumptions!$B$23*L10+(1-Assumptions!$B$23)*R10 -> 0.079729764 | Y10: =Assumptions!$B$24*M10+(1-Assumptions!$B$24)*S10 -> 0.13306165 | Z10: =Assumptions!$B$27*(1+T10) -> 360367.49 | AA10: =(Z10+Assumptions!$B$28)*(1+U10) -> 571587.91 | AB10: =AA10*(1+V10) -> 647508.48 | AC10: =AB10*(1+W10) -> 722163.61 | AD10: =AC10*(1+X10) -> 779741.54 | AE10: =AD10*(1+Y10) -> 883495.24 | AF10: =Z10 -> 360367.49 | AG10: =MAX(AF10,AA10) -> 571587.91 | AH10: =MAX(AG10,AB10) -> 647508.48 | AI10: =MAX(AH10,AC10) -> 722163.61 | AJ10: =MAX(AI10,AD10) -> 779741.54 | AK10: =MAX(AJ10,AE10) -> 883495.24 | AL10: =MIN(Z10/AF10-1,AA10/AG10-1,AB10/AH10-1,AC10/AI10-1,AD10/AJ10-1,AE10/AK10-1) -> 0 | AM10: =AE10-Assumptions!$B$35 -> 442231.24
A11: =ROW()-1 -> 10 | B11: =IF(RAND()<Assumptions!$B$11,"Bull","Bear") -> Bull | C11: =IF(B11="Bull",IF(RAND()<Assumptions!$B$7,"Bull","Bear"),IF(RAND()<Assumptions!$B$10,"Bear","Bull")) -> Bear | D11: =IF(C11="Bull",IF(RAND()<Assumptions!$B$7,"Bull","Bear"),IF(RAND()<Assumptions!$B$10,"Bear","Bull")) -> Bear | E11: =IF(D11="Bull",IF(RAND()<Assumptions!$B$7,"Bull","Bear"),IF(RAND()<Assumptions!$B$10,"Bear","Bull")) -> Bull | F11: =IF(E11="Bull",IF(RAND()<Assumptions!$B$7,"Bull","Bear"),IF(RAND()<Assumptions!$B$10,"Bear","Bull")) -> Bull | G11: =IF(F11="Bull",IF(RAND()<Assumptions!$B$7,"Bull","Bear"),IF(RAND()<Assumptions!$B$10,"Bear","Bull")) -> Bull | H11: =IF(B11="Bull",NORMINV(RAND(),Assumptions!$B$5,Assumptions!$B$6),NORMINV(RAND(),Assumptions!$B$8,Assumptions!$B$9)) -> 0.21038042 | I11: =IF(C11="Bull",NORMINV(RAND(),Assumptions!$B$5,Assumptions!$B$6),NORMINV(RAND(),Assumptions!$B$8,Assumptions!$B$9)) -> -0.23540049 | J11: =IF(D11="Bull",NORMINV(RAND(),Assumptions!$B$5,Assumptions!$B$6),NORMINV(RAND(),Assumptions!$B$8,Assumptions!$B$9)) -> -0.063395855 | K11: =IF(E11="Bull",NORMINV(RAND(),Assumptions!$B$5,Assumptions!$B$6),NORMINV(RAND(),Assumptions!$B$8,Assumptions!$B$9)) -> 0.22387146 | L11: =IF(F11="Bull",NORMINV(RAND(),Assumptions!$B$5,Assumptions!$B$6),NORMINV(RAND(),Assumptions!$B$8,Assumptions!$B$9)) -> 0.18442566 | M11: =IF(G11="Bull",NORMINV(RAND(),Assumptions!$B$5,Assumptions!$B$6),NORMINV(RAND(),Assumptions!$B$8,Assumptions!$B$9)) -> 0.073332113 | N11: =NORMINV(RAND(),Assumptions!$B$14,Assumptions!$B$15) -> 0.010493162 | O11: =NORMINV(RAND(),Assumptions!$B$14,Assumptions!$B$15) -> 0.043796304 | P11: =NORMINV(RAND(),Assumptions!$B$14,Assumptions!$B$15) -> 0.042406545 | Q11: =NORMINV(RAND(),Assumptions!$B$14,Assumptions!$B$15) -> 0.03994686 | R11: =NORMINV(RAND(),Assumptions!$B$14,Assumptions!$B$15) -> 0.054287162 | S11: =NORMINV(RAND(),Assumptions!$B$14,Assumptions!$B$15) -> 0.036208169 | T11: =Assumptions!$B$19*H11+(1-Assumptions!$B$19)*N11 -> 0.21038042 | U11: =Assumptions!$B$20*I11+(1-Assumptions!$B$20)*O11 -> -0.23540049 | V11: =Assumptions!$B$21*J11+(1-Assumptions!$B$21)*P11 -> -0.063395855 | W11: =Assumptions!$B$22*K11+(1-Assumptions!$B$22)*Q11 -> 0.22387146 | X11: =Assumptions!$B$23*L11+(1-Assumptions!$B$23)*R11 -> 0.15839796 | Y11: =Assumptions!$B$24*M11+(1-Assumptions!$B$24)*S11 -> 0.058482536 | Z11: =Assumptions!$B$27*(1+T11) -> 363114.13 | AA11: =(Z11+Assumptions!$B$28)*(1+U11) -> 392326.81 | AB11: =AA11*(1+V11) -> 367454.92 | AC11: =AB11*(1+W11) -> 449717.59 | AD11: =AC11*(1+X11) -> 520951.93 | AE11: =AD11*(1+Y11) -> 551418.52 | AF11: =Z11 -> 363114.13 | AG11: =MAX(AF11,AA11) -> 392326.81 | AH11: =MAX(AG11,AB11) -> 392326.81 | AI11: =MAX(AH11,AC11) -> 449717.59 | AJ11: =MAX(AI11,AD11) -> 520951.93 | AK11: =MAX(AJ11,AE11) -> 551418.52 | AL11: =MIN(Z11/AF11-1,AA11/AG11-1,AB11/AH11-1,AC11/AI11-1,AD11/AJ11-1,AE11/AK11-1) -> -0.063395855 | AM11: =AE11-Assumptions!$B$35 -> 110154.53
A12: =ROW()-1 -> 11 | B12: =IF(RAND()<Assumptions!$B$11,"Bull","Bear") -> Bear | C12: =IF(B12="Bull",IF(RAND()<Assumptions!$B$7,"Bull","Bear"),IF(RAND()<Assumptions!$B$10,"Bear","Bull")) -> Bull | D12: =IF(C12="Bull",IF(RAND()<Assumptions!$B$7,"Bull","Bear"),IF(RAND()<Assumptions!$B$10,"Bear","Bull")) -> Bear | E12: =IF(D12="Bull",IF(RAND()<Assumptions!$B$7,"Bull","Bear"),IF(RAND()<Assumptions!$B$10,"Bear","Bull")) -> Bull | F12: =IF(E12="Bull",IF(RAND()<Assumptions!$B$7,"Bull","Bear"),IF(RAND()<Assumptions!$B$10,"Bear","Bull")) -> Bear | G12: =IF(F12="Bull",IF(RAND()<Assumptions!$B$7,"Bull","Bear"),IF(RAND()<Assumptions!$B$10,"Bear","Bull")) -> Bull | H12: =IF(B12="Bull",NORMINV(RAND(),Assumptions!$B$5,Assumptions!$B$6),NORMINV(RAND(),Assumptions!$B$8,Assumptions!$B$9)) -> 0.29857109 | I12: =IF(C12="Bull",NORMINV(RAND(),Assumptions!$B$5,Assumptions!$B$6),NORMINV(RAND(),Assumptions!$B$8,Assumptions!$B$9)) -> 0.29398112 | J12: =IF(D12="Bull",NORMINV(RAND(),Assumptions!$B$5,Assumptions!$B$6),NORMINV(RAND(),Assumptions!$B$8,Assumptions!$B$9)) -> -0.16763059 | K12: =IF(E12="Bull",NORMINV(RAND(),Assumptions!$B$5,Assumptions!$B$6),NORMINV(RAND(),Assumptions!$B$8,Assumptions!$B$9)) -> 0.35726064 | L12: =IF(F12="Bull",NORMINV(RAND(),Assumptions!$B$5,Assumptions!$B$6),NORMINV(RAND(),Assumptions!$B$8,Assumptions!$B$9)) -> -0.26527491 | M12: =IF(G12="Bull",NORMINV(RAND(),Assumptions!$B$5,Assumptions!$B$6),NORMINV(RAND(),Assumptions!$B$8,Assumptions!$B$9)) -> -0.13173861 | N12: =NORMINV(RAND(),Assumptions!$B$14,Assumptions!$B$15) -> 0.10436975 | O12: =NORMINV(RAND(),Assumptions!$B$14,Assumptions!$B$15) -> 0.092741062 | P12: =NORMINV(RAND(),Assumptions!$B$14,Assumptions!$B$15) -> 0.021848229 | Q12: =NORMINV(RAND(),Assumptions!$B$14,Assumptions!$B$15) -> 0.0073587834 | R12: =NORMINV(RAND(),Assumptions!$B$14,Assumptions!$B$15) -> 0.11071413 | S12: =NORMINV(RAND(),Assumptions!$B$14,Assumptions!$B$15) -> 0.011764791 | T12: =Assumptions!$B$19*H12+(1-Assumptions!$B$19)*N12 -> 0.29857109 | U12: =Assumptions!$B$20*I12+(1-Assumptions!$B$20)*O12 -> 0.29398112 | V12: =Assumptions!$B$21*J12+(1-Assumptions!$B$21)*P12 -> -0.16763059 | W12: =Assumptions!$B$22*K12+(1-Assumptions!$B$22)*Q12 -> 0.35726064 | X12: =Assumptions!$B$23*L12+(1-Assumptions!$B$23)*R12 -> -0.1900771 | Y12: =Assumptions!$B$24*M12+(1-Assumptions!$B$24)*S12 -> -0.07433725 | Z12: =Assumptions!$B$27*(1+T12) -> 389571.33 | AA12: =(Z12+Assumptions!$B$28)*(1+U12) -> 698195.11 | AB12: =AA12*(1+V12) -> 581156.25 | AC12: =AB12*(1+W12) -> 788780.5 | AD12: =AC12*(1+X12) -> 638851.39 | AE12: =AD12*(1+Y12) -> 591360.93 | AF12: =Z12 -> 389571.33 | AG12: =MAX(AF12,AA12) -> 698195.11 | AH12: =MAX(AG12,AB12) -> 698195.11 | AI12: =MAX(AH12,AC12) -> 788780.5 | AJ12: =MAX(AI12,AD12) -> 788780.5 | AK12: =MAX(AJ12,AE12) -> 788780.5 | AL12: =MIN(Z12/AF12-1,AA12/AG12-1,AB12/AH12-1,AC12/AI12-1,AD12/AJ12-1,AE12/AK12-1) -> -0.25028454 | AM12: =AE12-Assumptions!$B$35 -> 150096.94
A13: =ROW()-1 -> 12 | B13: =IF(RAND()<Assumptions!$B$11,"Bull","Bear") -> Bear | C13: =IF(B13="Bull",IF(RAND()<Assumptions!$B$7,"Bull","Bear"),IF(RAND()<Assumptions!$B$10,"Bear","Bull")) -> Bull | D13: =IF(C13="Bull",IF(RAND()<Assumptions!$B$7,"Bull","Bear"),IF(RAND()<Assumptions!$B$10,"Bear","Bull")) -> Bear | E13: =IF(D13="Bull",IF(RAND()<Assumptions!$B$7,"Bull","Bear"),IF(RAND()<Assumptions!$B$10,"Bear","Bull")) -> Bear | F13: =IF(E13="Bull",IF(RAND()<Assumptions!$B$7,"Bull","Bear"),IF(RAND()<Assumptions!$B$10,"Bear","Bull")) -> Bear | G13: =IF(F13="Bull",IF(RAND()<Assumptions!$B$7,"Bull","Bear"),IF(RAND()<Assumptions!$B$10,"Bear","Bull")) -> Bull | H13: =IF(B13="Bull",NORMINV(RAND(),Assumptions!$B$5,Assumptions!$B$6),NORMINV(RAND(),Assumptions!$B$8,Assumptions!$B$9)) -> -0.063115213 | I13: =IF(C13="Bull",NORMINV(RAND(),Assumptions!$B$5,Assumptions!$B$6),NORMINV(RAND(),Assumptions!$B$8,Assumptions!$B$9)) -> 0.10683037 | J13: =IF(D13="Bull",NORMINV(RAND(),Assumptions!$B$5,Assumptions!$B$6),NORMINV(RAND(),Assumptions!$B$8,Assumptions!$B$9)) -> 0.19382988 | K13: =IF(E13="Bull",NORMINV(RAND(),Assumptions!$B$5,Assumptions!$B$6),NORMINV(RAND(),Assumptions!$B$8,Assumptions!$B$9)) -> 0.076035819 | L13: =IF(F13="Bull",NORMINV(RAND(),Assumptions!$B$5,Assumptions!$B$6),NORMINV(RAND(),Assumptions!$B$8,Assumptions!$B$9)) -> -0.14621137 | M13: =IF(G13="Bull",NORMINV(RAND(),Assumptions!$B$5,Assumptions!$B$6),NORMINV(RAND(),Assumptions!$B$8,Assumptions!$B$9)) -> 0.23554622 | N13: =NORMINV(RAND(),Assumptions!$B$14,Assumptions!$B$15) -> 0.03903954 | O13: =NORMINV(RAND(),Assumptions!$B$14,Assumptions!$B$15) -> 0.045037003 | P13: =NORMINV(RAND(),Assumptions!$B$14,Assumptions!$B$15) -> 0.087223312 | Q13: =NORMINV(RAND(),Assumptions!$B$14,Assumptions!$B$15) -> 0.073320635 | R13: =NORMINV(RAND(),Assumptions!$B$14,Assumptions!$B$15) -> 0.085167001 | S13: =NORMINV(RAND(),Assumptions!$B$14,Assumptions!$B$15) -> 0.049331516 | T13: =Assumptions!$B$19*H13+(1-Assumptions!$B$19)*N13 -> -0.063115213 | U13: =Assumptions!$B$20*I13+(1-Assumptions!$B$20)*O13 -> 0.10683037 | V13: =Assumptions!$B$21*J13+(1-Assumptions!$B$21)*P13 -> 0.19382988 | W13: =Assumptions!$B$22*K13+(1-Assumptions!$B$22)*Q13 -> 0.076035819 | X13: =Assumptions!$B$23*L13+(1-Assumptions!$B$23)*R13 -> -0.099935699 | Y13: =Assumptions!$B$24*M13+(1-Assumptions!$B$24)*S13 -> 0.16106034 | Z13: =Assumptions!$B$27*(1+T13) -> 281065.44 | AA13: =(Z13+Assumptions!$B$28)*(1+U13) -> 477116.32 | AB13: =AA13*(1+V13) -> 569595.71 | AC13: =AB13*(1+W13) -> 612905.39 | AD13: =AC13*(1+X13) -> 551654.26 | AE13: =AD13*(1+Y13) -> 640503.88 | AF13: =Z13 -> 281065.44 | AG13: =MAX(AF13,AA13) -> 477116.32 | AH13: =MAX(AG13,AB13) -> 569595.71 | AI13: =MAX(AH13,AC13) -> 612905.39 | AJ13: =MAX(AI13,AD13) -> 612905.39 | AK13: =MAX(AJ13,AE13) -> 640503.88 | AL13: =MIN(Z13/AF13-1,AA13/AG13-1,AB13/AH13-1,AC13/AI13-1,AD13/AJ13-1,AE13/AK13-1) -> -0.099935699 | AM13: =AE13-Assumptions!$B$35 -> 199239.89
... A501: =ROW()-1 -> 500 | B501: =IF(RAND()<Assumptions!$B$11,"Bull","Bear") -> Bull | C501: =IF(B501="Bull",IF(RAND()<Assumptions!$B$7,"Bull","Bear"),IF(RAND()<Assumptions!$B$10,"Bear","Bull")) -> Bear | D501: =IF(C501="Bull",IF(RAND()<Assumptions!$B$7,"Bull","Bear"),IF(RAND()<Assumptions!$B$10,"Bear","Bull")) -> Bull | E501: =IF(D501="Bull",IF(RAND()<Assumptions!$B$7,"Bull","Bear"),IF(RAND()<Assumptions!$B$10,"Bear","Bull")) -> Bear | F501: =IF(E501="Bull",IF(RAND()<Assumptions!$B$7,"Bull","Bear"),IF(RAND()<Assumptions!$B$10,"Bear","Bull")) -> Bull | G501: =IF(F501="Bull",IF(RAND()<Assumptions!$B$7,"Bull","Bear"),IF(RAND()<Assumptions!$B$10,"Bear","Bull")) -> Bull | H501: =IF(B501="Bull",NORMINV(RAND(),Assumptions!$B$5,Assumptions!$B$6),NORMINV(RAND(),Assumptions!$B$8,Assumptions!$B$9)) -> 0.10570808 | I501: =IF(C501="Bull",NORMINV(RAND(),Assumptions!$B$5,Assumptions!$B$6),NORMINV(RAND(),Assumptions!$B$8,Assumptions!$B$9)) -> -0.14630186 | J501: =IF(D501="Bull",NORMINV(RAND(),Assumptions!$B$5,Assumptions!$B$6),NORMINV(RAND(),Assumptions!$B$8,Assumptions!$B$9)) -> 0.29532591 | K501: =IF(E501="Bull",NORMINV(RAND(),Assumptions!$B$5,Assumptions!$B$6),NORMINV(RAND(),Assumptions!$B$8,Assumptions!$B$9)) -> -0.016432033 | L501: =IF(F501="Bull",NORMINV(RAND(),Assumptions!$B$5,Assumptions!$B$6),NORMINV(RAND(),Assumptions!$B$8,Assumptions!$B$9)) -> 0.14647244 | M501: =IF(G501="Bull",NORMINV(RAND(),Assumptions!$B$5,Assumptions!$B$6),NORMINV(RAND(),Assumptions!$B$8,Assumptions!$B$9)) -> 0.23574513 | N501: =NORMINV(RAND(),Assumptions!$B$14,Assumptions!$B$15) -> 0.043050014 | O501: =NORMINV(RAND(),Assumptions!$B$14,Assumptions!$B$15) -> 0.025761225 | P501: =NORMINV(RAND(),Assumptions!$B$14,Assumptions!$B$15) -> 0.050898051 | Q501: =NORMINV(RAND(),Assumptions!$B$14,Assumptions!$B$15) -> 0.069335214 | R501: =NORMINV(RAND(),Assumptions!$B$14,Assumptions!$B$15) -> 0.07056464 | S501: =NORMINV(RAND(),Assumptions!$B$14,Assumptions!$B$15) -> 0.10245232 | T501: =Assumptions!$B$19*H501+(1-Assumptions!$B$19)*N501 -> 0.10570808 | U501: =Assumptions!$B$20*I501+(1-Assumptions!$B$20)*O501 -> -0.14630186 | V501: =Assumptions!$B$21*J501+(1-Assumptions!$B$21)*P501 -> 0.29532591 | W501: =Assumptions!$B$22*K501+(1-Assumptions!$B$22)*Q501 -> -0.016432033 | X501: =Assumptions!$B$23*L501+(1-Assumptions!$B$23)*R501 -> 0.13129088 | Y501: =Assumptions!$B$24*M501+(1-Assumptions!$B$24)*S501 -> 0.18242801 | Z501: =Assumptions!$B$27*(1+T501) -> 331712.42 | AA501: =(Z501+Assumptions!$B$28)*(1+U501) -> 411237 | AB501: =AA501*(1+V501) -> 532685.94 | AC501: =AB501*(1+W501) -> 523932.83 | AD501: =AC501*(1+X501) -> 592720.43 | AE501: =AD501*(1+Y501) -> 700849.23 | AF501: =Z501 -> 331712.42 | AG501: =MAX(AF501,AA501) -> 411237 | AH501: =MAX(AG501,AB501) -> 532685.94 | AI501: =MAX(AH501,AC501) -> 532685.94 | AJ501: =MAX(AI501,AD501) -> 592720.43 | AK501: =MAX(AJ501,AE501) -> 700849.23 | AL501: =MIN(Z501/AF501-1,AA501/AG501-1,AB501/AH501-1,AC501/AI501-1,AD501/AJ501-1,AE501/AK501-1) -> -0.016432033 | AM501: =AE501-Assumptions!$B$35 -> 259585.24

Sheet Reserve_MC
A1: Trial | B1: Reserve Size ($) | C1: Return 2033 | D1: Return 2034 | E1: Return 2035 | F1: Return 2036 | G1: Return 2037 | H1: Return 2038 | I1: Return 2039 | J1: Return 2040 | K1: Return 2041 | L1: Return 2042 | M1: Bal. After Pmt 2033 ($) | N1: Bal. After Pmt 2034 ($) | O1: Bal. After Pmt 2035 ($) | P1: Bal. After Pmt 2036 ($) | Q1: Bal. After Pmt 2037 ($) | R1: Bal. After Pmt 2038 ($) | S1: Bal. After Pmt 2039 ($) | T1: Bal. After Pmt 2040 ($) | U1: Bal. After Pmt 2041 ($) | V1: Bal. After Pmt 2042 ($) | W1: Bal. End 2033 ($) | X1: Bal. End 2034 ($) | Y1: Bal. End 2035 ($) | Z1: Bal. End 2036 ($) | AA1: Bal. End 2037 ($) | AB1: Bal. End 2038 ($) | AC1: Bal. End 2039 ($) | AD1: Bal. End 2040 ($) | AE1: Bal. End 2041 ($) | AF1: Bal. End 2042 ($) | AG1: Min Balance After Any Payment ($) | AH1: All 10 Payments Fully Funded? (1=Yes)
A2: =ROW()-1 -> 1 | B2: =Assumptions!$B$35 -> 441264 | C2: =NORMINV(RAND(),Assumptions!$B$14,Assumptions!$B$15) -> 0.051252673 | D2: =NORMINV(RAND(),Assumptions!$B$14,Assumptions!$B$15) -> 0.041434958 | E2: =NORMINV(RAND(),Assumptions!$B$14,Assumptions!$B$15) -> 0.057651326 | F2: =NORMINV(RAND(),Assumptions!$B$14,Assumptions!$B$15) -> 0.081200505 | G2: =NORMINV(RAND(),Assumptions!$B$14,Assumptions!$B$15) -> 0.030039576 | H2: =NORMINV(RAND(),Assumptions!$B$14,Assumptions!$B$15) -> -0.005838768 | I2: =NORMINV(RAND(),Assumptions!$B$14,Assumptions!$B$15) -> 0.092278763 | J2: =NORMINV(RAND(),Assumptions!$B$14,Assumptions!$B$15) -> -0.0017086626 | ... L2: =NORMINV(RAND(),Assumptions!$B$14,Assumptions!$B$15) -> 0.06729735 | M2: =B2-Assumptions!$B$29 -> 391264 | N2: =W2-Assumptions!$B$29 -> 361317.32 | O2: =X2-Assumptions!$B$29 -> 326288.49 | P2: =Y2-Assumptions!$B$29 -> 295099.45 | Q2: =Z2-Assumptions!$B$29 -> 269061.68 | R2: =AA2-Assumptions!$B$29 -> 227144.18 | S2: =AB2-Assumptions!$B$29 -> 175817.94 | T2: =AC2-Assumptions!$B$29 -> 142042.2 | U2: =AD2-Assumptions!$B$29 -> 91799.495 | V2: =AE2-Assumptions!$B$29 -> 47382.23 | W2: =M2*(1+C2) -> 411317.32 | X2: =N2*(1+D2) -> 376288.49 | Y2: =O2*(1+E2) -> 345099.45 | Z2: =P2*(1+F2) -> 319061.68 | AA2: =Q2*(1+G2) -> 277144.18 | AB2: =R2*(1+H2) -> 225817.94 | AC2: =S2*(1+I2) -> 192042.2 | AD2: =T2*(1+J2) -> 141799.49 | ... AF2: =V2*(1+L2) -> 50570.929 | AG2: =MIN(M2:V2) -> 47382.23 | AH2: =IF(AG2>=0,1,0) -> 1
A3: =ROW()-1 -> 2 | B3: =Assumptions!$B$35 -> 441264 | C3: =NORMINV(RAND(),Assumptions!$B$14,Assumptions!$B$15) -> 0.015858051 | D3: =NORMINV(RAND(),Assumptions!$B$14,Assumptions!$B$15) -> 0.016093719 | E3: =NORMINV(RAND(),Assumptions!$B$14,Assumptions!$B$15) -> 0.050996173 | F3: =NORMINV(RAND(),Assumptions!$B$14,Assumptions!$B$15) -> 0.075501702 | G3: =NORMINV(RAND(),Assumptions!$B$14,Assumptions!$B$15) -> 0.054537218 | H3: =NORMINV(RAND(),Assumptions!$B$14,Assumptions!$B$15) -> 0.087969816 | I3: =NORMINV(RAND(),Assumptions!$B$14,Assumptions!$B$15) -> 0.042472547 | J3: =NORMINV(RAND(),Assumptions!$B$14,Assumptions!$B$15) -> 0.046744366 | ... L3: =NORMINV(RAND(),Assumptions!$B$14,Assumptions!$B$15) -> 0.060817463 | M3: =B3-Assumptions!$B$29 -> 391264 | N3: =W3-Assumptions!$B$29 -> 347468.68 | O3: =X3-Assumptions!$B$29 -> 303060.74 | P3: =Y3-Assumptions!$B$29 -> 268515.68 | Q3: =Z3-Assumptions!$B$29 -> 238789.07 | R3: =AA3-Assumptions!$B$29 -> 201811.97 | S3: =AB3-Assumptions!$B$29 -> 169565.33 | T3: =AC3-Assumptions!$B$29 -> 126767.2 | U3: =AD3-Assumptions!$B$29 -> 82692.851 | V3: =AE3-Assumptions!$B$29 -> 35178.164 | W3: =M3*(1+C3) -> 397468.68 | X3: =N3*(1+D3) -> 353060.74 | Y3: =O3*(1+E3) -> 318515.68 | Z3: =P3*(1+F3) -> 288789.07 | AA3: =Q3*(1+G3) -> 251811.97 | AB3: =R3*(1+H3) -> 219565.33 | AC3: =S3*(1+I3) -> 176767.2 | AD3: =T3*(1+J3) -> 132692.85 | ... AF3: =V3*(1+L3) -> 37317.61 | AG3: =MIN(M3:V3) -> 35178.164 | AH3: =IF(AG3>=0,1,0) -> 1
A4: =ROW()-1 -> 3 | B4: =Assumptions!$B$35 -> 441264 | C4: =NORMINV(RAND(),Assumptions!$B$14,Assumptions!$B$15) -> 0.04645689 | D4: =NORMINV(RAND(),Assumptions!$B$14,Assumptions!$B$15) -> 0.068406664 | E4: =NORMINV(RAND(),Assumptions!$B$14,Assumptions!$B$15) -> 0.049417357 | F4: =NORMINV(RAND(),Assumptions!$B$14,Assumptions!$B$15) -> 0.071584877 | G4: =NORMINV(RAND(),Assumptions!$B$14,Assumptions!$B$15) -> 0.048916589 | H4: =NORMINV(RAND(),Assumptions!$B$14,Assumptions!$B$15) -> 0.063462254 | I4: =NORMINV(RAND(),Assumptions!$B$14,Assumptions!$B$15) -> 0.092984641 | J4: =NORMINV(RAND(),Assumptions!$B$14,Assumptions!$B$15) -> 0.0070857868 | ... L4: =NORMINV(RAND(),Assumptions!$B$14,Assumptions!$B$15) -> 0.057578823 | M4: =B4-Assumptions!$B$29 -> 391264 | N4: =W4-Assumptions!$B$29 -> 359440.91 | O4: =X4-Assumptions!$B$29 -> 334029.06 | P4: =Y4-Assumptions!$B$29 -> 300535.89 | Q4: =Z4-Assumptions!$B$29 -> 272049.72 | R4: =AA4-Assumptions!$B$29 -> 235357.46 | S4: =AB4-Assumptions!$B$29 -> 200293.78 | T4: =AC4-Assumptions!$B$29 -> 168918.02 | U4: =AD4-Assumptions!$B$29 -> 120114.94 | V4: =AE4-Assumptions!$B$29 -> 80948.584 | W4: =M4*(1+C4) -> 409440.91 | X4: =N4*(1+D4) -> 384029.06 | Y4: =O4*(1+E4) -> 350535.89 | Z4: =P4*(1+F4) -> 322049.72 | AA4: =Q4*(1+G4) -> 285357.46 | AB4: =R4*(1+H4) -> 250293.78 | AC4: =S4*(1+I4) -> 218918.02 | AD4: =T4*(1+J4) -> 170114.94 | ... AF4: =V4*(1+L4) -> 85609.508 | AG4: =MIN(M4:V4) -> 80948.584 | AH4: =IF(AG4>=0,1,0) -> 1
A5: =ROW()-1 -> 4 | B5: =Assumptions!$B$35 -> 441264 | C5: =NORMINV(RAND(),Assumptions!$B$14,Assumptions!$B$15) -> 0.10981201 | D5: =NORMINV(RAND(),Assumptions!$B$14,Assumptions!$B$15) -> 0.028951634 | E5: =NORMINV(RAND(),Assumptions!$B$14,Assumptions!$B$15) -> 0.040912248 | F5: =NORMINV(RAND(),Assumptions!$B$14,Assumptions!$B$15) -> 0.02615128 | G5: =NORMINV(RAND(),Assumptions!$B$14,Assumptions!$B$15) -> 0.042698539 | H5: =NORMINV(RAND(),Assumptions!$B$14,Assumptions!$B$15) -> 0.092283503 | I5: =NORMINV(RAND(),Assumptions!$B$14,Assumptions!$B$15) -> 0.076678958 | J5: =NORMINV(RAND(),Assumptions!$B$14,Assumptions!$B$15) -> 0.082239889 | ... L5: =NORMINV(RAND(),Assumptions!$B$14,Assumptions!$B$15) -> 0.040558681 | M5: =B5-Assumptions!$B$29 -> 391264 | N5: =W5-Assumptions!$B$29 -> 384229.48 | O5: =X5-Assumptions!$B$29 -> 345353.55 | P5: =Y5-Assumptions!$B$29 -> 309482.74 | Q5: =Z5-Assumptions!$B$29 -> 267576.11 | R5: =AA5-Assumptions!$B$29 -> 229001.22 | S5: =AB5-Assumptions!$B$29 -> 200134.26 | T5: =AC5-Assumptions!$B$29 -> 165480.34 | U5: =AD5-Assumptions!$B$29 -> 129089.43 | V5: =AE5-Assumptions!$B$29 -> 88801.765 | W5: =M5*(1+C5) -> 434229.48 | X5: =N5*(1+D5) -> 395353.55 | Y5: =O5*(1+E5) -> 359482.74 | Z5: =P5*(1+F5) -> 317576.11 | AA5: =Q5*(1+G5) -> 279001.22 | AB5: =R5*(1+H5) -> 250134.26 | AC5: =S5*(1+I5) -> 215480.34 | AD5: =T5*(1+J5) -> 179089.43 | ... AF5: =V5*(1+L5) -> 92403.448 | AG5: =MIN(M5:V5) -> 88801.765 | AH5: =IF(AG5>=0,1,0) -> 1
A6: =ROW()-1 -> 5 | B6: =Assumptions!$B$35 -> 441264 | C6: =NORMINV(RAND(),Assumptions!$B$14,Assumptions!$B$15) -> 0.089800016 | D6: =NORMINV(RAND(),Assumptions!$B$14,Assumptions!$B$15) -> 0.038354891 | E6: =NORMINV(RAND(),Assumptions!$B$14,Assumptions!$B$15) -> 0.064614216 | F6: =NORMINV(RAND(),Assumptions!$B$14,Assumptions!$B$15) -> 0.028581261 | G6: =NORMINV(RAND(),Assumptions!$B$14,Assumptions!$B$15) -> 0.029192209 | H6: =NORMINV(RAND(),Assumptions!$B$14,Assumptions!$B$15) -> 0.053469354 | I6: =NORMINV(RAND(),Assumptions!$B$14,Assumptions!$B$15) -> 0.021553112 | J6: =NORMINV(RAND(),Assumptions!$B$14,Assumptions!$B$15) -> 0.04292698 | ... L6: =NORMINV(RAND(),Assumptions!$B$14,Assumptions!$B$15) -> 0.02775442 | M6: =B6-Assumptions!$B$29 -> 391264 | N6: =W6-Assumptions!$B$29 -> 376399.51 | O6: =X6-Assumptions!$B$29 -> 340836.27 | P6: =Y6-Assumptions!$B$29 -> 312859.14 | Q6: =Z6-Assumptions!$B$29 -> 271801.05 | R6: =AA6-Assumptions!$B$29 -> 229735.52 | S6: =AB6-Assumptions!$B$29 -> 192019.33 | T6: =AC6-Assumptions!$B$29 -> 146157.95 | U6: =AD6-Assumptions!$B$29 -> 102432.07 | V6: =AE6-Assumptions!$B$29 -> 54243.832 | W6: =M6*(1+C6) -> 426399.51 | X6: =N6*(1+D6) -> 390836.27 | Y6: =O6*(1+E6) -> 362859.14 | Z6: =P6*(1+F6) -> 321801.05 | AA6: =Q6*(1+G6) -> 279735.52 | AB6: =R6*(1+H6) -> 242019.33 | AC6: =S6*(1+I6) -> 196157.95 | AD6: =T6*(1+J6) -> 152432.07 | ... AF6: =V6*(1+L6) -> 55749.338 | AG6: =MIN(M6:V6) -> 54243.832 | AH6: =IF(AG6>=0,1,0) -> 1
A7: =ROW()-1 -> 6 | B7: =Assumptions!$B$35 -> 441264 | C7: =NORMINV(RAND(),Assumptions!$B$14,Assumptions!$B$15) -> 0.00071094676 | D7: =NORMINV(RAND(),Assumptions!$B$14,Assumptions!$B$15) -> 0.075162332 | E7: =NORMINV(RAND(),Assumptions!$B$14,Assumptions!$B$15) -> 0.072013704 | F7: =NORMINV(RAND(),Assumptions!$B$14,Assumptions!$B$15) -> 0.05161613 | G7: =NORMINV(RAND(),Assumptions!$B$14,Assumptions!$B$15) -> 0.069315503 | H7: =NORMINV(RAND(),Assumptions!$B$14,Assumptions!$B$15) -> 0.026622342 | I7: =NORMINV(RAND(),Assumptions!$B$14,Assumptions!$B$15) -> 0.076053949 | J7: =NORMINV(RAND(),Assumptions!$B$14,Assumptions!$B$15) -> 0.033334879 | ... L7: =NORMINV(RAND(),Assumptions!$B$14,Assumptions!$B$15) -> 0.020058574 | M7: =B7-Assumptions!$B$29 -> 391264 | N7: =W7-Assumptions!$B$29 -> 341542.16 | O7: =X7-Assumptions!$B$29 -> 317213.27 | P7: =Y7-Assumptions!$B$29 -> 290056.97 | Q7: =Z7-Assumptions!$B$29 -> 255028.59 | R7: =AA7-Assumptions!$B$29 -> 222706.03 | S7: =AB7-Assumptions!$B$29 -> 178634.98 | T7: =AC7-Assumptions!$B$29 -> 142220.88 | U7: =AD7-Assumptions!$B$29 -> 96961.794 | V7: =AE7-Assumptions!$B$29 -> 57043.489 | W7: =M7*(1+C7) -> 391542.16 | X7: =N7*(1+D7) -> 367213.27 | Y7: =O7*(1+E7) -> 340056.97 | Z7: =P7*(1+F7) -> 305028.59 | AA7: =Q7*(1+G7) -> 272706.03 | AB7: =R7*(1+H7) -> 228634.98 | AC7: =S7*(1+I7) -> 192220.88 | AD7: =T7*(1+J7) -> 146961.79 | ... AF7: =V7*(1+L7) -> 58187.7 | AG7: =MIN(M7:V7) -> 57043.489 | AH7: =IF(AG7>=0,1,0) -> 1
A8: =ROW()-1 -> 7 | B8: =Assumptions!$B$35 -> 441264 | C8: =NORMINV(RAND(),Assumptions!$B$14,Assumptions!$B$15) -> 0.047255488 | D8: =NORMINV(RAND(),Assumptions!$B$14,Assumptions!$B$15) -> 0.034511806 | E8: =NORMINV(RAND(),Assumptions!$B$14,Assumptions!$B$15) -> 0.011102929 | F8: =NORMINV(RAND(),Assumptions!$B$14,Assumptions!$B$15) -> 0.025976961 | G8: =NORMINV(RAND(),Assumptions!$B$14,Assumptions!$B$15) -> 0.034610781 | H8: =NORMINV(RAND(),Assumptions!$B$14,Assumptions!$B$15) -> 0.09801883 | I8: =NORMINV(RAND(),Assumptions!$B$14,Assumptions!$B$15) -> 0.059897485 | J8: =NORMINV(RAND(),Assumptions!$B$14,Assumptions!$B$15) -> 0.073327232 | ... L8: =NORMINV(RAND(),Assumptions!$B$14,Assumptions!$B$15) -> 0.05276095 | M8: =B8-Assumptions!$B$29 -> 391264 | N8: =W8-Assumptions!$B$29 -> 359753.37 | O8: =X8-Assumptions!$B$29 -> 322169.11 | P8: =Y8-Assumptions!$B$29 -> 275746.13 | Q8: =Z8-Assumptions!$B$29 -> 232909.17 | R8: =AA8-Assumptions!$B$29 -> 190970.34 | S8: =AB8-Assumptions!$B$29 -> 159689.03 | T8: =AC8-Assumptions!$B$29 -> 119254 | U8: =AD8-Assumptions!$B$29 -> 77998.568 | V8: =AE8-Assumptions!$B$29 -> 30541.112 | W8: =M8*(1+C8) -> 409753.37 | X8: =N8*(1+D8) -> 372169.11 | Y8: =O8*(1+E8) -> 325746.13 | Z8: =P8*(1+F8) -> 282909.17 | AA8: =Q8*(1+G8) -> 240970.34 | AB8: =R8*(1+H8) -> 209689.03 | AC8: =S8*(1+I8) -> 169254 | AD8: =T8*(1+J8) -> 127998.57 | ... AF8: =V8*(1+L8) -> 32152.49 | AG8: =MIN(M8:V8) -> 30541.112 | AH8: =IF(AG8>=0,1,0) -> 1
A9: =ROW()-1 -> 8 | B9: =Assumptions!$B$35 -> 441264 | C9: =NORMINV(RAND(),Assumptions!$B$14,Assumptions!$B$15) -> 0.051213149 | D9: =NORMINV(RAND(),Assumptions!$B$14,Assumptions!$B$15) -> 0.029087572 | E9: =NORMINV(RAND(),Assumptions!$B$14,Assumptions!$B$15) -> 0.039962011 | F9: =NORMINV(RAND(),Assumptions!$B$14,Assumptions!$B$15) -> 0.03327797 | G9: =NORMINV(RAND(),Assumptions!$B$14,Assumptions!$B$15) -> 0.076365066 | H9: =NORMINV(RAND(),Assumptions!$B$14,Assumptions!$B$15) -> 0.046826673 | I9: =NORMINV(RAND(),Assumptions!$B$14,Assumptions!$B$15) -> -0.0067310579 | J9: =NORMINV(RAND(),Assumptions!$B$14,Assumptions!$B$15) -> 0.040599343 | ... L9: =NORMINV(RAND(),Assumptions!$B$14,Assumptions!$B$15) -> 0.09420835 | M9: =B9-Assumptions!$B$29 -> 391264 | N9: =W9-Assumptions!$B$29 -> 361301.86 | O9: =X9-Assumptions!$B$29 -> 321811.25 | P9: =Y9-Assumptions!$B$29 -> 284671.48 | Q9: =Z9-Assumptions!$B$29 -> 244144.77 | R9: =AA9-Assumptions!$B$29 -> 212788.9 | S9: =AB9-Assumptions!$B$29 -> 172753.09 | T9: =AC9-Assumptions!$B$29 -> 121590.28 | U9: =AD9-Assumptions!$B$29 -> 76526.767 | V9: =AE9-Assumptions!$B$29 -> 26012.68 | W9: =M9*(1+C9) -> 411301.86 | X9: =N9*(1+D9) -> 371811.25 | Y9: =O9*(1+E9) -> 334671.48 | Z9: =P9*(1+F9) -> 294144.77 | AA9: =Q9*(1+G9) -> 262788.9 | AB9: =R9*(1+H9) -> 222753.09 | AC9: =S9*(1+I9) -> 171590.28 | AD9: =T9*(1+J9) -> 126526.77 | ... AF9: =V9*(1+L9) -> 28463.292 | AG9: =MIN(M9:V9) -> 26012.68 | AH9: =IF(AG9>=0,1,0) -> 1
